reported_result/report-4/ART_TFC/output/output7.txt

Limit	1	7	6	5	2	SELL	0	---	0
NewOrderRs	Accepted
	Trades	0
	Orders	1
	Order	Limit	1	7	6	5	2	SELL	0	---	0
	Credits	7
	Credit	1	15
	Credit	2	15
	Credit	3	6
	Credit	4	7
	Credit	5	5
	Credit	6	12
	Credit	7	7
	Ownerships	7
	Ownership	1	58
	Ownership	2	36
	Ownership	3	65
	Ownership	4	51
	Ownership	5	26
	Ownership	6	54
	Ownership	7	33
	ReferencePrice	5
	StaticPriceBandLowerLimit	0.6
	StaticPriceBandUpperLimit	0.8
	TotalShares	100
	OwnershipUpperLimit	0.2
	TickSize	1
	LotSize	1
Iceberg	2	2	6	10	3	BUY 	0	---	0
NewOrderRs	Rejected
	Trades	0
	Orders	1
	Order	Limit	1	7	6	5	2	SELL	0	---	0
	Credits	7
	Credit	1	15
	Credit	2	15
	Credit	3	6
	Credit	4	7
	Credit	5	5
	Credit	6	12
	Credit	7	7
	Ownerships	7
	Ownership	1	58
	Ownership	2	36
	Ownership	3	65
	Ownership	4	51
	Ownership	5	26
	Ownership	6	54
	Ownership	7	33
	ReferencePrice	5
	StaticPriceBandLowerLimit	0.6
	StaticPriceBandUpperLimit	0.8
	TotalShares	100
	OwnershipUpperLimit	0.2
	TickSize	1
	LotSize	1
Iceberg	3	5	6	3	2	BUY 	2	---	0
NewOrderRs	Rejected
	Trades	0
	Orders	1
	Order	Limit	1	7	6	5	2	SELL	0	---	0
	Credits	7
	Credit	1	15
	Credit	2	15
	Credit	3	6
	Credit	4	7
	Credit	5	5
	Credit	6	12
	Credit	7	7
	Ownerships	7
	Ownership	1	58
	Ownership	2	36
	Ownership	3	65
	Ownership	4	51
	Ownership	5	26
	Ownership	6	54
	Ownership	7	33
	ReferencePrice	5
	StaticPriceBandLowerLimit	0.6
	StaticPriceBandUpperLimit	0.8
	TotalShares	100
	OwnershipUpperLimit	0.2
	TickSize	1
	LotSize	1
Limit	4	5	2	10	6	SELL	0	---	0
NewOrderRs	Rejected
	Trades	0
	Orders	1
	Order	Limit	1	7	6	5	2	SELL	0	---	0
	Credits	7
	Credit	1	15
	Credit	2	15
	Credit	3	6
	Credit	4	7
	Credit	5	5
	Credit	6	12
	Credit	7	7
	Ownerships	7
	Ownership	1	58
	Ownership	2	36
	Ownership	3	65
	Ownership	4	51
	Ownership	5	26
	Ownership	6	54
	Ownership	7	33
	ReferencePrice	5
	StaticPriceBandLowerLimit	0.6
	StaticPriceBandUpperLimit	0.8
	TotalShares	100
	OwnershipUpperLimit	0.2
	TickSize	1
	LotSize	1
CancelOrderRs	Rejected
	Orders	1
	Order	Limit	1	7	6	5	2	SELL	0	---	0
	Credits	7
	Credit	1	15
	Credit	2	15
	Credit	3	6
	Credit	4	7
	Credit	5	5
	Credit	6	12
	Credit	7	7
	Ownerships	7
	Ownership	1	58
	Ownership	2	36
	Ownership	3	65
	Ownership	4	51
	Ownership	5	26
	Ownership	6	54
	Ownership	7	33
	ReferencePrice	5
	StaticPriceBandLowerLimit	0.6
	StaticPriceBandUpperLimit	0.8
	TotalShares	100
	OwnershipUpperLimit	0.2
	TickSize	1
	LotSize	1
Iceberg	6	5	4	9	7	SELL	0	---	0
NewOrderRs	Accepted
	Trades	0
	Orders	2
	Order	Limit	1	7	6	5	2	SELL	0	---	0
	Order	Iceberg	6	5	4	9	7	SELL	0	---	3
	Credits	7
	Credit	1	15
	Credit	2	15
	Credit	3	6
	Credit	4	7
	Credit	5	5
	Credit	6	12
	Credit	7	7
	Ownerships	7
	Ownership	1	58
	Ownership	2	36
	Ownership	3	65
	Ownership	4	51
	Ownership	5	26
	Ownership	6	54
	Ownership	7	33
	ReferencePrice	5
	StaticPriceBandLowerLimit	0.6
	StaticPriceBandUpperLimit	0.8
	TotalShares	100
	OwnershipUpperLimit	0.2
	TickSize	1
	LotSize	1
Iceberg	7	3	4	3	8	SELL	5	---	0
NewOrderRs	Eliminated
	Trades	0
	Orders	2
	Order	Limit	1	7	6	5	2	SELL	0	---	0
	Order	Iceberg	6	5	4	9	7	SELL	0	---	3
	Credits	7
	Credit	1	15
	Credit	2	15
	Credit	3	6
	Credit	4	7
	Credit	5	5
	Credit	6	12
	Credit	7	7
	Ownerships	7
	Ownership	1	58
	Ownership	2	36
	Ownership	3	65
	Ownership	4	51
	Ownership	5	26
	Ownership	6	54
	Ownership	7	33
	ReferencePrice	5
	StaticPriceBandLowerLimit	0.6
	StaticPriceBandUpperLimit	0.8
	TotalShares	100
	OwnershipUpperLimit	0.2
	TickSize	1
	LotSize	1
Iceberg	8	5	7	5	7	BUY 	0	---	0
NewOrderRs	Rejected
	Trades	0
	Orders	2
	Order	Limit	1	7	6	5	2	SELL	0	---	0
	Order	Iceberg	6	5	4	9	7	SELL	0	---	3
	Credits	7
	Credit	1	15
	Credit	2	15
	Credit	3	6
	Credit	4	7
	Credit	5	5
	Credit	6	12
	Credit	7	7
	Ownerships	7
	Ownership	1	58
	Ownership	2	36
	Ownership	3	65
	Ownership	4	51
	Ownership	5	26
	Ownership	6	54
	Ownership	7	33
	ReferencePrice	5
	StaticPriceBandLowerLimit	0.6
	StaticPriceBandUpperLimit	0.8
	TotalShares	100
	OwnershipUpperLimit	0.2
	TickSize	1
	LotSize	1
Iceberg	9	5	1	6	6	SELL	0	---	0
NewOrderRs	Accepted
	Trades	0
	Orders	3
	Order	Limit	1	7	6	5	2	SELL	0	---	0
	Order	Iceberg	9	5	1	6	6	SELL	0	---	4
	Order	Iceberg	6	5	4	9	7	SELL	0	---	3
	Credits	7
	Credit	1	15
	Credit	2	15
	Credit	3	6
	Credit	4	7
	Credit	5	5
	Credit	6	12
	Credit	7	7
	Ownerships	7
	Ownership	1	58
	Ownership	2	36
	Ownership	3	65
	Ownership	4	51
	Ownership	5	26
	Ownership	6	54
	Ownership	7	33
	ReferencePrice	5
	StaticPriceBandLowerLimit	0.6
	StaticPriceBandUpperLimit	0.8
	TotalShares	100
	OwnershipUpperLimit	0.2
	TickSize	1
	LotSize	1
Limit	10	5	1	7	4	SELL	0	---	0
ReplaceOrderRs	Accepted
	Trades	0
	Orders	3
	Order	Limit	1	7	6	5	2	SELL	0	---	0
	Order	Limit	10	5	1	7	4	SELL	0	---	0
	Order	Iceberg	6	5	4	9	7	SELL	0	---	3
	Credits	7
	Credit	1	15
	Credit	2	15
	Credit	3	6
	Credit	4	7
	Credit	5	5
	Credit	6	12
	Credit	7	7
	Ownerships	7
	Ownership	1	58
	Ownership	2	36
	Ownership	3	65
	Ownership	4	51
	Ownership	5	26
	Ownership	6	54
	Ownership	7	33
	ReferencePrice	5
	StaticPriceBandLowerLimit	0.6
	StaticPriceBandUpperLimit	0.8
	TotalShares	100
	OwnershipUpperLimit	0.2
	TickSize	1
	LotSize	1
Iceberg	11	1	4	7	1	SELL	0	---	0
NewOrderRs	Accepted
	Trades	0
	Orders	4
	Order	Limit	1	7	6	5	2	SELL	0	---	0
	Order	Limit	10	5	1	7	4	SELL	0	---	0
	Order	Iceberg	11	1	4	7	1	SELL	0	---	1
	Order	Iceberg	6	5	4	9	7	SELL	0	---	3
	Credits	7
	Credit	1	15
	Credit	2	15
	Credit	3	6
	Credit	4	7
	Credit	5	5
	Credit	6	12
	Credit	7	7
	Ownerships	7
	Ownership	1	58
	Ownership	2	36
	Ownership	3	65
	Ownership	4	51
	Ownership	5	26
	Ownership	6	54
	Ownership	7	33
	ReferencePrice	5
	StaticPriceBandLowerLimit	0.6
	StaticPriceBandUpperLimit	0.8
	TotalShares	100
	OwnershipUpperLimit	0.2
	TickSize	1
	LotSize	1
Limit	12	4	6	10	8	BUY 	0	---	0
NewOrderRs	Rejected
	Trades	0
	Orders	4
	Order	Limit	1	7	6	5	2	SELL	0	---	0
	Order	Limit	10	5	1	7	4	SELL	0	---	0
	Order	Iceberg	11	1	4	7	1	SELL	0	---	1
	Order	Iceberg	6	5	4	9	7	SELL	0	---	3
	Credits	7
	Credit	1	15
	Credit	2	15
	Credit	3	6
	Credit	4	7
	Credit	5	5
	Credit	6	12
	Credit	7	7
	Ownerships	7
	Ownership	1	58
	Ownership	2	36
	Ownership	3	65
	Ownership	4	51
	Ownership	5	26
	Ownership	6	54
	Ownership	7	33
	ReferencePrice	5
	StaticPriceBandLowerLimit	0.6
	StaticPriceBandUpperLimit	0.8
	TotalShares	100
	OwnershipUpperLimit	0.2
	TickSize	1
	LotSize	1
Limit	13	5	5	5	2	BUY 	2	---	0
NewOrderRs	Rejected
	Trades	0
	Orders	4
	Order	Limit	1	7	6	5	2	SELL	0	---	0
	Order	Limit	10	5	1	7	4	SELL	0	---	0
	Order	Iceberg	11	1	4	7	1	SELL	0	---	1
	Order	Iceberg	6	5	4	9	7	SELL	0	---	3
	Credits	7
	Credit	1	15
	Credit	2	15
	Credit	3	6
	Credit	4	7
	Credit	5	5
	Credit	6	12
	Credit	7	7
	Ownerships	7
	Ownership	1	58
	Ownership	2	36
	Ownership	3	65
	Ownership	4	51
	Ownership	5	26
	Ownership	6	54
	Ownership	7	33
	ReferencePrice	5
	StaticPriceBandLowerLimit	0.6
	StaticPriceBandUpperLimit	0.8
	TotalShares	100
	OwnershipUpperLimit	0.2
	TickSize	1
	LotSize	1
Limit	14	6	6	2	6	BUY 	0	---	0
NewOrderRs	Rejected
	Trades	0
	Orders	4
	Order	Limit	1	7	6	5	2	SELL	0	---	0
	Order	Limit	10	5	1	7	4	SELL	0	---	0
	Order	Iceberg	11	1	4	7	1	SELL	0	---	1
	Order	Iceberg	6	5	4	9	7	SELL	0	---	3
	Credits	7
	Credit	1	15
	Credit	2	15
	Credit	3	6
	Credit	4	7
	Credit	5	5
	Credit	6	12
	Credit	7	7
	Ownerships	7
	Ownership	1	58
	Ownership	2	36
	Ownership	3	65
	Ownership	4	51
	Ownership	5	26
	Ownership	6	54
	Ownership	7	33
	ReferencePrice	5
	StaticPriceBandLowerLimit	0.6
	StaticPriceBandUpperLimit	0.8
	TotalShares	100
	OwnershipUpperLimit	0.2
	TickSize	1
	LotSize	1
CancelOrderRs	Rejected
	Orders	4
	Order	Limit	1	7	6	5	2	SELL	0	---	0
	Order	Limit	10	5	1	7	4	SELL	0	---	0
	Order	Iceberg	11	1	4	7	1	SELL	0	---	1
	Order	Iceberg	6	5	4	9	7	SELL	0	---	3
	Credits	7
	Credit	1	15
	Credit	2	15
	Credit	3	6
	Credit	4	7
	Credit	5	5
	Credit	6	12
	Credit	7	7
	Ownerships	7
	Ownership	1	58
	Ownership	2	36
	Ownership	3	65
	Ownership	4	51
	Ownership	5	26
	Ownership	6	54
	Ownership	7	33
	ReferencePrice	5
	StaticPriceBandLowerLimit	0.6
	StaticPriceBandUpperLimit	0.8
	TotalShares	100
	OwnershipUpperLimit	0.2
	TickSize	1
	LotSize	1
Iceberg	16	3	3	10	3	SELL	1	---	0
NewOrderRs	Rejected
	Trades	0
	Orders	4
	Order	Limit	1	7	6	5	2	SELL	0	---	0
