reported_result/report-4/ART_TFClustering/output/output15.txt

Iceberg	1	3	7	8	5	SELL	0	---	0
NewOrderRs	Accepted
	Trades	0
	Orders	1
	Order	Iceberg	1	3	7	8	5	SELL	0	---	4
	Credits	7
	Credit	1	12
	Credit	2	19
	Credit	3	14
	Credit	4	10
	Credit	5	17
	Credit	6	18
	Credit	7	6
	Ownerships	7
	Ownership	1	29
	Ownership	2	22
	Ownership	3	14
	Ownership	4	51
	Ownership	5	38
	Ownership	6	34
	Ownership	7	11
	ReferencePrice	5
	StaticPriceBandLowerLimit	0.6
	StaticPriceBandUpperLimit	0.8
	TotalShares	100
	OwnershipUpperLimit	0.2
	TickSize	1
	LotSize	1
Iceberg	2	6	2	9	8	SELL	5	---	0
NewOrderRs	Eliminated
	Trades	0
	Orders	1
	Order	Iceberg	1	3	7	8	5	SELL	0	---	4
	Credits	7
	Credit	1	12
	Credit	2	19
	Credit	3	14
	Credit	4	10
	Credit	5	17
	Credit	6	18
	Credit	7	6
	Ownerships	7
	Ownership	1	29
	Ownership	2	22
	Ownership	3	14
	Ownership	4	51
	Ownership	5	38
	Ownership	6	34
	Ownership	7	11
	ReferencePrice	5
	StaticPriceBandLowerLimit	0.6
	StaticPriceBandUpperLimit	0.8
	TotalShares	100
	OwnershipUpperLimit	0.2
	TickSize	1
	LotSize	1
Limit	3	2	6	9	5	SELL	0	---	0
NewOrderRs	Accepted
	Trades	0
	Orders	2
	Order	Iceberg	1	3	7	8	5	SELL	0	---	4
	Order	Limit	3	2	6	9	5	SELL	0	---	0
	Credits	7
	Credit	1	12
	Credit	2	19
	Credit	3	14
	Credit	4	10
	Credit	5	17
	Credit	6	18
	Credit	7	6
	Ownerships	7
	Ownership	1	29
	Ownership	2	22
	Ownership	3	14
	Ownership	4	51
	Ownership	5	38
	Ownership	6	34
	Ownership	7	11
	ReferencePrice	5
	StaticPriceBandLowerLimit	0.6
	StaticPriceBandUpperLimit	0.8
	TotalShares	100
	OwnershipUpperLimit	0.2
	TickSize	1
	LotSize	1
Iceberg	4	7	2	4	1	BUY 	1	---	0
NewOrderRs	Rejected
	Trades	0
	Orders	2
	Order	Iceberg	1	3	7	8	5	SELL	0	---	4
	Order	Limit	3	2	6	9	5	SELL	0	---	0
	Credits	7
	Credit	1	12
	Credit	2	19
	Credit	3	14
	Credit	4	10
	Credit	5	17
	Credit	6	18
	Credit	7	6
	Ownerships	7
	Ownership	1	29
	Ownership	2	22
	Ownership	3	14
	Ownership	4	51
	Ownership	5	38
	Ownership	6	34
	Ownership	7	11
	ReferencePrice	5
	StaticPriceBandLowerLimit	0.6
	StaticPriceBandUpperLimit	0.8
	TotalShares	100
	OwnershipUpperLimit	0.2
	TickSize	1
	LotSize	1
CancelOrderRs	Rejected
	Orders	2
	Order	Iceberg	1	3	7	8	5	SELL	0	---	4
	Order	Limit	3	2	6	9	5	SELL	0	---	0
	Credits	7
	Credit	1	12
	Credit	2	19
	Credit	3	14
	Credit	4	10
	Credit	5	17
	Credit	6	18
	Credit	7	6
	Ownerships	7
	Ownership	1	29
	Ownership	2	22
	Ownership	3	14
	Ownership	4	51
	Ownership	5	38
	Ownership	6	34
	Ownership	7	11
	ReferencePrice	5
	StaticPriceBandLowerLimit	0.6
	StaticPriceBandUpperLimit	0.8
	TotalShares	100
	OwnershipUpperLimit	0.2
	TickSize	1
	LotSize	1
Limit	6	5	7	6	7	BUY 	0	FAK	0
NewOrderRs	Eliminated
	Trades	0
	Orders	2
	Order	Iceberg	1	3	7	8	5	SELL	0	---	4
	Order	Limit	3	2	6	9	5	SELL	0	---	0
	Credits	7
	Credit	1	12
	Credit	2	19
	Credit	3	14
	Credit	4	10
	Credit	5	17
	Credit	6	18
	Credit	7	6
	Ownerships	7
	Ownership	1	29
	Ownership	2	22
	Ownership	3	14
	Ownership	4	51
	Ownership	5	38
	Ownership	6	34
	Ownership	7	11
	ReferencePrice	5
	StaticPriceBandLowerLimit	0.6
	StaticPriceBandUpperLimit	0.8
	TotalShares	100
	OwnershipUpperLimit	0.2
	TickSize	1
	LotSize	1
Limit	7	6	6	4	6	BUY 	0	---	0
NewOrderRs	Rejected
	Trades	0
	Orders	2
	Order	Iceberg	1	3	7	8	5	SELL	0	---	4
	Order	Limit	3	2	6	9	5	SELL	0	---	0
	Credits	7
	Credit	1	12
	Credit	2	19
	Credit	3	14
	Credit	4	10
	Credit	5	17
	Credit	6	18
	Credit	7	6
	Ownerships	7
	Ownership	1	29
	Ownership	2	22
	Ownership	3	14
	Ownership	4	51
	Ownership	5	38
	Ownership	6	34
	Ownership	7	11
	ReferencePrice	5
	StaticPriceBandLowerLimit	0.6
	StaticPriceBandUpperLimit	0.8
	TotalShares	100
	OwnershipUpperLimit	0.2
	TickSize	1
	LotSize	1
Limit	8	7	7	4	3	BUY 	0	---	0
NewOrderRs	Rejected
	Trades	0
	Orders	2
	Order	Iceberg	1	3	7	8	5	SELL	0	---	4
	Order	Limit	3	2	6	9	5	SELL	0	---	0
	Credits	7
	Credit	1	12
	Credit	2	19
	Credit	3	14
	Credit	4	10
	Credit	5	17
	Credit	6	18
	Credit	7	6
	Ownerships	7
	Ownership	1	29
	Ownership	2	22
	Ownership	3	14
	Ownership	4	51
	Ownership	5	38
	Ownership	6	34
	Ownership	7	11
	ReferencePrice	5
	StaticPriceBandLowerLimit	0.6
	StaticPriceBandUpperLimit	0.8
	TotalShares	100
	OwnershipUpperLimit	0.2
	TickSize	1
	LotSize	1
Limit	9	2	1	4	6	SELL	0	FAK	0
NewOrderRs	Eliminated
	Trades	0
	Orders	2
	Order	Iceberg	1	3	7	8	5	SELL	0	---	4
	Order	Limit	3	2	6	9	5	SELL	0	---	0
	Credits	7
	Credit	1	12
	Credit	2	19
	Credit	3	14
	Credit	4	10
	Credit	5	17
	Credit	6	18
	Credit	7	6
	Ownerships	7
	Ownership	1	29
	Ownership	2	22
	Ownership	3	14
	Ownership	4	51
	Ownership	5	38
	Ownership	6	34
	Ownership	7	11
	ReferencePrice	5
	StaticPriceBandLowerLimit	0.6
	StaticPriceBandUpperLimit	0.8
	TotalShares	100
	OwnershipUpperLimit	0.2
	TickSize	1
	LotSize	1
Limit	10	2	1	6	6	SELL	6	---	0
ReplaceOrderRs	Rejected
	Trades	0
	Orders	2
	Order	Iceberg	1	3	7	8	5	SELL	0	---	4
	Order	Limit	3	2	6	9	5	SELL	0	---	0
	Credits	7
	Credit	1	12
	Credit	2	19
	Credit	3	14
	Credit	4	10
	Credit	5	17
	Credit	6	18
	Credit	7	6
	Ownerships	7
	Ownership	1	29
	Ownership	2	22
	Ownership	3	14
	Ownership	4	51
	Ownership	5	38
	Ownership	6	34
	Ownership	7	11
	ReferencePrice	5
	StaticPriceBandLowerLimit	0.6
	StaticPriceBandUpperLimit	0.8
	TotalShares	100
	OwnershipUpperLimit	0.2
	TickSize	1
	LotSize	1
